Workbook
Name LISTA2: #REF!
Name LISTA2: #REF!
Name LISTA: #REF!
Name LISTA: #REF!
Name CONDIÇÕES: LEGENDAS!$B$2:$B$15
Name Z_924C3F12_84CF_4ABF_87A7_8BDDD9B8FFC3_.wvu.Cols: #REF!
Name Z_8ACAB7D4_A245_4B01_A455_8574F923850F_.wvu.Cols: #REF!
Name QD: #REF!
Name Z_211FD241_5063_4A4F_BCF7_C47C7F4BF783_.wvu.Cols: #REF!
Name listadoida: #REF!
Name QD: #REF!
Name listaprodutos: #REF!

Sheet PEDIDOS
A1: PEDIDO | B1: CLIENTE | C1: QTY EM ESTOQUE | D1: ORDEM DE PRODUCAO | E1: MODELO | F1: CONTROL | G1: OPCIONAL | H1: ESQ ESF | I1: SITUACAO | J1: TRANSPORTADORA | K1: REDESPACHO | L1: NOTA FISCAL | M1: EXPEDIDO POR | N1: VEICULO | O1: DATA ENTREGA | P1: OBSERVAÇÃO | Q1: INTEGRADO POR | R1: APROVADO POR | S1: FINALIZADO POR | T1: DATA INTEGRAÇÃO | U1: DATA APROVAÇÃO | V1: DATA FINALIZAÇÃO | W1: VOLUMES | X1: DATA DA ENTREGA FUTURA | Y1: IMPRESSAO LOGISTICA | Z1: IMPRESSAO PRODUCAO | AA1: Estado | AB1: 🔒 Row ID | AC1: Qty
A2: 9315 | B2: ODY PARK | C2: 0 | D2: N INF | E2: FT240H35T | F2: TOUCH | G2: SOBREPOR | H2: NAO | I2: ENTREGUE | J2: DESTAK | K2: SEM REDESPACHO | L2: 10979 | M2: RUBENS F | N2: QJC5G74 - DESTAK - MOHAMAD KASSEM RAHHAL JUNIOR - 75084600954 - FIAT / DUCATO CHASSI L / PRATA / 2018 | O2: 45461.605 | P2: RETORNO OS - 2605 | T2: 45460 | U2: 45460 | V2: =O2 -> 45461.605 | AB2: CEpVgkCBTDG1O.g7S56G7g
A3: 18684-A | B3: ANDRADES PISCINAS E AQUECEDORES LTDA | C3: 41 | D3: 8A00240411003121 | E3: FTI125D40PT | F3: WI-FI | G3: NAO | H3: NAO | I3: ENTREGUE | J3: FITLOG | K3: SEM REDESPACHO | L3: 14061 | M3: Eduardo Gasperi (Expedição) | N3: KKY4B29 - V2 - RODRIGO NEZIO GRADICI - 07157615959 - FORD/CARGO 1317 E / CARAGA CAMINHAO / PRATA / 2010 | O3: 45489.644 | P3: PR170 - PEDIDO 15704 DA ANDRADE PISCINAS AGUARDANDO PAGAMENTO | T3: 45489.644 | V3: 45489.589 | AB3: gP.DutRRSzK5nyW2GD.yJw
A4: 18684-B | B4: ANDRADES PISCINAS E AQUECEDORES LTDA | C4: 41 | D4: 8A00240411003124 | E4: FTI125D40PT | F4: WI-FI | G4: NAO | H4: NAO | I4: ENTREGUE | J4: FITLOG | K4: SEM REDESPACHO | L4: 14061 | M4: Eduardo Gasperi (Expedição) | N4: KKY4B29 - V2 - RODRIGO NEZIO GRADICI - 07157615959 - FORD/CARGO 1317 E / CARAGA CAMINHAO / PRATA / 2010 | O4: 45489.644 | P4: PR176 - PEDIDO 15704 DA ANDRADE PISCINAS AGUARDANDO PAGAMENTO | T4: 45489.644 | V4: 45489.589 | AB4: w7Hs2zo1Sj21Y-qGz5Gqew
A5: PR177 | B5: ANDRADES PISCINAS E AQUECEDORES LTDA | C5: 41 | D5: 8A00240411003144 | E5: FTI125D40PT | F5: WI-FI | G5: NAO | H5: NAO | I5: FILIAL PARANA | J5: FITLOG | K5: SEM REDESPACHO | L5: 14061 | M5: Eduardo Gasperi (Expedição) | N5: KKY4B29 - V2 - RODRIGO NEZIO GRADICI - 07157615959 - FORD/CARGO 1317 E / CARAGA CAMINHAO / PRATA / 2010 | O5: 45489.644 | P5: PR177 - DISPONIVEL ULT CONTAGEM 04/11 | T5: 45489.644 | V5: 45489.589 | AB5: Tcma2JeES9W00VrrQ1zhPg
A6: 16454 | B6: PISCINA E LAZER | C6: 41 | D6: 8A00240411003115 | E6: FTI125D40PT | F6: WI-FI | G6: NAO | H6: NAO | I6: ENTREGUE | J6: EXPRESSO SAO MIGUEL | K6: SEM REDESPACHO | L6: 11969 | M6: Eduardo Gasperi (Expedição) | N6: KKY4B29 - V2 - RODRIGO NEZIO GRADICI - 07157615959 - FORD/CARGO 1317 E / CARAGA CAMINHAO / PRATA / 2010 | O6: 45608.453 | P6: PR184 - DISPONIVEL ULT CONTAGEM 04/11 ESTOQUE CURITIBA - PR 184 Pedido nº 1585 enviado pelo vendedor Renato criado em 11/11/2024 09:31:28 integrado por meio do Bendito no dia 11/11/2024 às 14:32:34 | Q6: Juliana Vieira | R6: Juliana Vieira | T6: 45608.453 | U6: 45608.453 | V6: 45608.453 | AB6: DWaTaqF8Su6ghTDxnrqqjw
A7: R14817 | B7: BR CERT LABORATORIOS LTDA. | C7: 12 | D7: 8F00240723280519 | E7: FTI45D40PT | G7: NAO | H7: NAO | I7: ENTREGUE | J7: FITLOG | K7: SEM REDESPACHO | L7: 12694 | M7: Jair Rodrigues (Logística) | O7: 45721 | P7: ORÇAMENTO Nº1287/2025 | Q7: Eline Velho | R7: Eline Velho | S7: Jair Rodrigues (Logística) | T7: 45716.565 | U7: 45716.565 | V7: 45716.587 | AB7: ho69gK3ERAS9-bddCsfFdQ
A8: 13832 | B8: UNIAO BR DE EDUCACAO E ASSITENCIA PUCRS | D8: 13832 | E8: FT40B35T | G8: NAO | H8: NAO | I8: ENTREGUE | J8: EXPRESSO SAO MIGUEL | K8: SEM REDESPACHO | L8: 12396 | M8: Eduardo Gasperi (Expedição) | N8: QJL1E51 - EXPRESSO SÃO MIGUEL - CLEIMAR CRESTANI - 07899108969 - VW / 17280 CRM 4X2 / BRANCO / 2017 | O8: 45665.636 | P8: MAQUINA CERTIFICAÇÃO INMETRO - PROVA | T8: 45665.636 | AB8: 5Smk4sB6RcqWjfxga99eZg
A9: 15537 | B9: BERCHA E TENCIANO LTDA | D9: 8B00240106003041 | E9: FTI55D40PT | F9: WI-FI | G9: NAO | H9: NAO | I9: ENTREGUE | J9: FITLOG | K9: SEM REDESPACHO | N9: OMG6C25 - FIT LOG - PAULO SERGIO AMARO - 03705266942 - M.BENZ / CARGA CAMINHAO / BRANCA / 2012 | O9: 45482 | P9: PR118 | T9: 45440 | U9: 45475 | V9: =O9 -> 45482 | AB9: cf1q6-QBQXmncHAlD5IvMw
A10: 15553 | B10: NAUSSAT PISCINAS | D10: 8B00231215003187 | E10: FTI75D40PT | F10: WI-FI | G10: NAO | H10: NAO | I10: ENTREGUE | J10: RETIRA | K10: SEM REDESPACHO | L10: 11171 | N10: FILIAL PARANA | O10: 45489 | P10: MAQUINA ESTOQUE PARTICULAR RENATO - COD.BARRAS - 31110003000092- 8B00231215003187 ANTES DA TABELA NOVA - ESSA MAQUINA ERA DO RENATO, FOI VENDIDA PRA ELE, ELE ATENDEU A NECESSIDADE DE UM CLIENTE VENDENDO A MAQUINA DELE PRO CLIENTE, SENDO ESSES DADOS ACIMA. NAO SEI QUAL É O PEDIDO ANTERIOR | Q10: Juliana Vieira | T10: 45489.741 | U10: 45489 | V10: OBSERVAÇÃO | AA10: PR | AB10: d6ixmBOgQnqJNVzraY5xuQ
A11: 15651 | B11: AQUALAR E/OU AQUALAR WATER SOLUTIONS | D11: 13514 | E11: FT180F35T | G11: SOBREPOR | H11: NAO | I11: ENTREGUE | J11: FITLOG | K11: SEM REDESPACHO | L11: 11208 | M11: Eduardo Gasperi (Expedição) | N11: MGH1012 - FIT LOG - ELIVELTO GONÇALVES DIAS - 07704779923 - VW / 8.150E DELIVERY / BRANCA / 2005 | O11: 45496.575 | P11: Quadro deslocado sobrepor. ENTRGAR N AQUALAR Mario-Autorizado( Composição de fechamento dos pre pedidos 751.752.823 e 824(integrados juntos) Pedido nº 752 enviado pelo vendedor Ricardo Henrique criado em 08/07/2024 14:18:08 integrado por meio do Bendito no dia 19/07/2024 às 10:27:08 POR FAVOR, NÃO ENTREGAR S/ENTRAR EM CONTATO COM O TELEFONE: 21 99512-4022 AO MENOS C/ 24H DE ANTECEDÊNCIA | Q11: Juliana Vieira | S11: Francisco/Rubens (Teste) | T11: 45492.447 | U11: 45492.452 | V11: 45495.671 | AA11: RJ | AB11: c8EoQN2fTsSTZrvQ1MM6Uw
A12: 15964 | B12: WILLIAN RAFAEL ALVES 06251787694 | D12: 8A00240514003010 | E12: FTI55D40PT | G12: NAO | H12: NAO | I12: ENTREGUE | J12: FITLOG | K12: SEM REDESPACHO | L12: 11472 | M12: Eduardo Gasperi (Expedição) | N12: ASE2851 - FIT LOG - RICARDO JORGE HAVIARA - 87153955968 - PEUGEOT / BOXER F350LH 23S / BRANCA / 2010 | O12: 45547.611 | P12: Frete com redespacho pela GRIFE - CNPJ: 25.406.384/0005-00 - GUARULHOS - R. IRAQUARA 24 - JARDIM IV CENTENARIO, GUARULHOS - SP, O cliente está com urgência da máquina. Pedido nº 1131 enviado pelo vendedor Luiz criado em 11/09/2024 10:34:20 integrado por meio do Bendito no dia 11/09/2024 às 10:36:18 O REDESPACHO SERA FOB - TRANSP. GRIFE - CNPJ:25.406.384/0005-00 - END: R IRAQUARA, 24, CEP: 07.161-550 | Q12: Juliana Vieira | R12: Juliana Vieira | S12: Eduardo Gasperi (Expedição) | T12: 45546.457 | U12: 45546.603 | V12: 45547.475 | AA12: MG | AB12: YE7yE-wZR6mYhh-R7oi5kg
A13: 16401 | B13: AQUAFIX EQUIPAMENTOS PARA PISCINAS | D13: 8B00240322003239 | E13: FTI105D40PT | F13: WI-FI | G13: NAO | H13: NAO | I13: ENTREGUE | J13: FITLOG | K13: SEM REDESPACHO | L13: 11933 | M13: Eduardo Gasperi (Expedição) | N13: KKY4B29 - V2 - RODRIGO NEZIO GRADICI - 07157615959 - FORD/CARGO 1317 E / CARAGA CAMINHAO / PRATA / 2010 | O13: 45489.644 | P13: ESTOQUE CURITIBA PR162 - O PEDIDO JA FOI RETIRADO PELO CLIENTE DA FILIAL PARANA, O PEDIDO ANTERIOR 15801 HAVIA SIDO CANCELADO, REABRIMOS O PEDIDO E MANTEREMOS A FORMA DE PAGAMENTO A VISTA, O PEDIDO AINDA NÃO CONSTA COMO PAGO. QUANDO O PEDIDO FOR PAGO FAVOR, FATURAR A NF E INFORMAR O JAIR | Q13: Juliana Vieira | R13: Juliana Vieira | T13: 45602.665 | U13: 45602.664 | V13: 45489.588 | AA13: PR | AB13: OVd2mcz0RSecKYwngcpZYg
A14: 16528 | B14: VERANO | D14: 13787 | E14: FT20B35T | G14: NAO | H14: NAO | I14: ENTREGUE | J14: RETIRA | K14: SEM REDESPACHO | L14: 12131 | M14: Eduardo Gasperi (Expedição) | N14: RHE5C97 - RETIRA - MARCOS VINICIUS DA SILVA CRUZ - 93307217291 - VW / CARGA CAMIONETE / BRANCA / 2022 | O14: 45637.66 | P14: CLIENTE TEM DESCONTO EXTRA DE + 8% NA LINHA FT PREÇO R$ 6.297,51 PEDIDO CLIENTE 24811 Pedido nº 1649 enviado pelo vendedor Carlos Augusto criado em 20/11/2024 08:15:58 integrado por meio do Bendito no dia 20/11/2024 às 09:18:03 | Q14: Juliana Vieira | R14: Juliana Vieira | S14: Francisco/Rubens (Teste) | T14: 45616.4 | U14: 45616.412 | V14: 45630.588 | AA14: SC | AB14: SORlhv1sRsCwRr2qBjI9kw
A15: 16713 | B15: MULTCOLOR | D15: 8F00241005160010 | E15: FTI75D40PT | G15: NAO | H15: NAO | I15: ENTREGUE | J15: FITLOG | K15: SEM REDESPACHO | L15: 12243 | M15: Eduardo Gasperi (Expedição) | N15: KET4256 - FITLOG - LEONARDO DE SOUSA ROCHA - 02043623931 - VW / 18.310 / BRANCA / 2003 | O15: 45645.731 | P15: cliente : ricardo martinez (parana) - (constar em NF) Pedido nº 1755 enviado pelo vendedor Fábio criado em 04/12/2024 10:09:17 integrado por meio do Bendito no dia 04/12/2024 às 10:16:40 | Q15: Juliana Vieira | R15: Juliana Vieira | S15: Jair Rodrigues (Logística) | T15: 45630.455 | U15: 45630.465 | V15: 45643.756 | Y15: -12166 | AA15: SP | AB15: vmtL7lMAS7ixxlsqVkDCrQ
A16: 16728 | B16: ROGER A.D BOARO | D16: 8F00240812180128 | E16: FTI45D40PT | G16: NAO | H16: NAO | I16: ENTREGUE | J16: FITLOG | K16: SEM REDESPACHO | L16: 12179 | M16: Eduardo Gasperi (Expedição) | N16: ASE2851 - FIT LOG - RICARDO JORGE HAVIARA - 87153955968 - PEUGEOT / BOXER F350LH 23S / BRANCA / 2010 | O16: 45637.626 | P16: AGUARDANDO ANALISE FINANCEIRA. O desconto no pedido foi autorizado pelo Mario pelo frete cotado no valor de R$163,33 Número da cotação: 164133 Mario-autorizado | Q16: Juliana Vieira | R16: Juliana Vieira | S16: Eduardo Gasperi (Expedição) | T16: 45636.448 | U16: 45636.449 | V16: 45636.45 | AA16: PR | AB16: yZR1RvSzRsWtnLP.QAtaMg
A17: 16792 | B17: Laboratório do Sol Aquecedores | D17: 13818 | E17: FTI145DPTBR | G17: NAO | H17: NAO | I17: ENTREGUE | J17: EXPRESSO SAO MIGUEL | K17: SEM REDESPACHO | L17: 12257 | M17: Eduardo Gasperi (Expedição) | N17: RLL3I15 - RETIRA - GUILHERME OURIQUES - - RENAUT / MASTER / BRANCA / 2022 | O17: 45652.491 | P17: VALOR DA BOMBA R$20852,00 - NA COR PRETA entrada+30/45/60/75/90 ds Pedido nº 1724 enviado pelo vendedor Carlos Augusto criado em 29/11/2024 15:02:54 integrado por meio do Bendito no dia 30/11/2024 às 07:28:48 | Q17: Juliana Vieira | R17: Juliana Vieira | S17: Rubens | T17: 45642.676 | U17: 45642.676 | V17: 45644 | AA17: SC | AB17: Ar3bnGnURhOWGqeCabtJkQ
A18: 17016 | B18: ILUSTRE SISTEMA DE ILUMINACAO | D18: 8F00241118050033 | E18: FTI75D40PT | G18: NAO | H18: NAO | I18: ENTREGUE | J18: FITLOG | K18: FORMATO | L18: 12554 | M18: Eduardo Gasperi (Expedição) | N18: MGH1012 - FITLOG - GIORLY BOMBUL - 11305672224 - VW / DELIVERY / BRANCA / 2015 | O18: 45691.595 | P18: R$10.221,86 em 10 x no cartão . Passar o link para Bruno Sampaio . TRANSPORTADORA : FORMATO TRANSPORTES LTDA-CNPJ: 13.727.240/0001-34 RUA RIO GRANDE DP PIAUI-130 CIDADE ARACILIA GUARULHOS SP -FONE 11 25367215- Pedido nº 2043 enviado pelo vendedor Mario criado em 31/01/2025 14:01:01 integrado por meio do Bendito no dia 31/01/2025 às 14:01:11 FORMATO TRANSPORTES LTDA-CNPJ: 13.727.240/0001-34 RUA RIO GRANDE DP PIAUI-130 CIDADE ARACILIA GUARULHOS SP -FONE 1125367215 | Q18: Eline Velho | R18: Eline Velho | S18: Eduardo Gasperi (Expedição) | T18: 45688.732 | U18: 45688.732 | V18: 45691.36 | AA18: BA | AB18: WTZySRbTRCSmb3.GCvH.iA
A19: 17042 | B19: NERCI MOREIRA | D19: 8F00241021270016 | E19: FTI105D40PT | G19: NAO | H19: NAO | I19: ENTREGUE | J19: EXPRESSO SAO MIGUEL | K19: SEM REDESPACHO | L19: 12580 | M19: Eduardo Gasperi (Expedição) | N19: RAA3F11 - EXPRESSO SÃO MIGUEL - ALIDEIA JUCHEM CRESTANI - 04171883903 - I KIA / UK2500 HD SC / BRANCA / 2022 | O19: 45694.598 | P19: OP ANTIGA 13958 ESTE PEDIDO COMPLETA O PEDIDO 17002, QUE DEVEERIA TER SIDO ENTREGUE 2 MAQUINAS E FOI ENTREGUE APENAS 1. Pedido nº 2032 enviado pelo vendedor Renato criado em 30/01/2025 13:24:04 integrado por meio do Bendito no dia 30/01/2025 às 14:19:51 | Q19: Eline Velho | R19: Jair Rodrigues | S19: Eduardo Gasperi (Expedição) | T19: 45693.512 | U19: 45693.551 | V19: 45694.345 | AA19: PR | AB19: ZB5icL8hQR-R.Fu.y94tEA
A20: 17181 | B20: GAROPABA PISCINAS | D20: 13954 | E20: FTI55DPTBR | G20: NAO | H20: NAO | I20: ENTREGUE | J20: RETIRA | K20: SEM REDESPACHO | L20: 12705 | M20: Jair Rodrigues (Logística) | N20: MHL9974 - RETIRA - VERA LUCIA CARDOSO LEMOS - 46915338004 - VW / SAVEIRO / PRETA / 2015 | O20: 45726.44 | P20: cliente retira . 07/03/25 Pedido nº 2186 enviado pelo vendedor Mario criado em 07/03/2025 15:01:18 integrado por meio do Bendito no dia 07/03/2025 às 15:01:28 | Q20: Eline Velho | R20: Eline Velho | T20: 45723.629 | U20: 45723.629 | AA20: SC | AB20: gr9Z3G9uSsWBLLxTf44U6A
A21: 17654 | B21: EXPRESSO SAO MIGUEL | D21: 8F00240723280539 | E21: FTI45D40PT | G21: NAO | H21: NAO | I21: ENTREGUE | J21: EXPRESSO SAO MIGUEL | K21: SEM REDESPACHO | L21: 13152 | P21: SAÍDA REFERENTE A RESSARCIMENTO DE MÁQUINA AVARIADA. - PEDIDO 17284 - NF-e 12866 APÓLICE DE SEGURO Nº | Q21: Jair Rodrigues (Logística) | R21: Jair Rodrigues (Logística) | S21: Jair Rodrigues (Logística) | T21: 45806.744 | U21: 45806.744 | V21: 45806.744 | AB21: WKuDpHSHRv2HpZudKA7Uuw
A22: 11488 | B22: BENE E BENI COMÉRCIO DE PISCINAS LTDA | D22: 11831 | E22: FT160F35T | F22: TOUCH | G22: SOBREPOR | H22: NAO | I22: ENTREGUE | J22: FITLOG | K22: SEM REDESPACHO | L22: 9744 | O22: 45198 | P22: FRETE CIF. | T22: 45195 | U22: 45195 | V22: 45197 | AB22: 0ih7WFstRquMj-AVoJEftw
A23: 13619-A | B23: ACQUANEW PISCINAS LTDA | C23: {=COUNTIFS('Estoque V2'!A:A,E23:E5893,'Estoque V2'!D:D,0,'Estoque V2'!C:C,F23)} -> 0 | D23: 8B00230924003126 | E23: FTI55D40CZ | F23: WI-FI | G23: NAO | H23: NAO | I23: ENTREGUE | J23: EXPRESSO SAO MIGUEL | K23: SEM REDESPACHO | L23: 9813-10212 | O23: 45308 | P23: CONDIÇÃO DE PAGAMENTO APROVADA PELO MARIO | T23: 45183 | U23: 45305 | V23: 45308 | AB23: GENH4wujRJCgI4PfoqIHxw
A24: 13619-B | B24: ACQUANEW PISCINAS LTDA | C24: 0 | D24: 8B00230927003031 | E24: FTI75D40CZ | F24: WI-FI | G24: NAO | H24: NAO | I24: ENTREGUE | J24: EXPRESSO SAO MIGUEL | K24: SEM REDESPACHO | L24: 9813-10212 | O24: 45308 | P24: CONDIÇÃO DE PAGAMENTO APROVADA PELO MARIO | T24: 45183 | U24: 45305 | V24: 45308 | AB24: dy6GHuyzTkiwO3DgMRdHBA
A25: 13619-C | B25: ACQUANEW PISCINAS LTDA | C25: 0 | D25: 8B00230927003060 | E25: FTI75D40CZ | F25: WI-FI | G25: NAO | H25: NAO | I25: ENTREGUE | J25: EXPRESSO SAO MIGUEL | K25: SEM REDESPACHO | L25: 9813-10212 | O25: 45308 | P25: CONDIÇÃO DE PAGAMENTO APROVADA PELO MARIO | T25: 45183 | U25: 45305 | V25: 45308 | AB25: lUdU1o.kSiO2CsJ4CE7PAw
A26: 13619-D | B26: ACQUANEW PISCINAS LTDA | C26: 0 | D26: 8B00230927003098 | E26: FTI105D40CZ | F26: WI-FI | G26: NAO | H26: NAO | I26: ENTREGUE | J26: EXPRESSO SAO MIGUEL | K26: SEM REDESPACHO | L26: 9813-10212 | O26: 45308 | P26: CONDIÇÃO DE PAGAMENTO APROVADA PELO MARIO | T26: 45183 | U26: 45305 | V26: 45308 | AB26: JhmbP0IbQUO7fTsPqLQvYQ
A27: 13619-E | B27: ACQUANEW PISCINAS LTDA | C27: 0 | D27: 8B00230927003112 | E27: FTI125D40CZ | F27: WI-FI | G27: NAO | H27: NAO | I27: ENTREGUE | J27: EXPRESSO SAO MIGUEL | K27: SEM REDESPACHO | L27: 9813-10212 | O27: 45308 | P27: CONDIÇÃO DE PAGAMENTO APROVADA PELO MARIO | T27: 45183 | U27: 45305 | V27: 45308 | AB27: J2ywZGqNRv2edywv8Ilq4Q
A28: 13619-F | B28: ACQUANEW PISCINAS LTDA | C28: 0 | D28: 8B00230924003178 | E28: FTI55D40CZ | F28: WI-FI | G28: NAO | H28: NAO | I28: ENTREGUE | J28: EXPRESSO SAO MIGUEL | K28: SEM REDESPACHO | L28: 9813-10212 | O28: 45308 | P28: CONDIÇÃO DE PAGAMENTO APROVADA PELO MARIO | T28: 45183 | U28: 45305 | V28: 45308 | AB28: DDu1qcXZQR6OJohn2Jj57g
A29: 13621-A | B29: ADRIANI APARECIDA BOTTEGA | C29: 0 | D29: 8B00230927003077 | E29: FTI75D40CZ | F29: WI-FI | G29: NAO | H29: NAO | I29: ENTREGUE | J29: EXPRESSO SAO MIGUEL | K29: SEM REDESPACHO | L29: 9861 | O29: 45310 | T29: 45197 | U29: 45307 | V29: 45310 | AB29: zLu7RaOaTBmZmmGDutM2YA
A30: 13621-B | B30: ADRIANI APARECIDA BOTTEGA | C30: 0 | D30: 8B00230927003055 | E30: FTI75D40CZ | F30: WI-FI | G30: NAO | H30: NAO | I30: ENTREGUE | J30: EXPRESSO SAO MIGUEL | K30: SEM REDESPACHO | L30: 9861 | O30: 45310 | T30: 45197 | U30: 45307 | V30: 45310 | AB30: TvJvz-r3Sp6dwFEKpGdOsg
A31: 13623-A | B31: CR DOS SANTOS | C31: 0 | D31: 11715 | E31: FT20B35T | F31: TOUCH | G31: SOBREPOR | H31: NAO | I31: ENTREGUE | J31: EXPRESSO M.LOG | K31: SEM REDESPACHO | L31: 9725 | O31: 45195 | T31: 45187 | U31: 45187 | V31: 45190 | AB31: zxFZlTq5SbKsdbm4k6o1UA
A32: 13623-B | B32: CR DOS SANTOS | C32: 0 | D32: 11789 | E32: FT40B35T | F32: TOUCH | G32: SOBREPOR | H32: NAO | I32: ENTREGUE | J32: EXPRESSO M.LOG | K32: SEM REDESPACHO | L32: 9725 | O32: 45195 | T32: 45187 | U32: 45187 | V32: 45190 | AB32: E0L224e-TYmQ1tWfYhX84g
A33: 13623-C | B33: CR DOS SANTOS | C33: 0 | D33: 11790 | E33: FT40B35T | F33: TOUCH | G33: SOBREPOR | H33: NAO | I33: ENTREGUE | J33: EXPRESSO M.LOG | K33: SEM REDESPACHO | L33: 9725 | O33: 45195 | T33: 45187 | U33: 45187 | V33: 45190 | AB33: Cp20CV7mTcWAK8KzHaOmpA
A34: 13623-D | B34: CR DOS SANTOS | C34: 0 | D34: 11791 | E34: FT50B35T | F34: TOUCH | G34: SOBREPOR | H34: NAO | I34: ENTREGUE | J34: EXPRESSO M.LOG | K34: SEM REDESPACHO | L34: 9725 | O34: 45195 | T34: 45187 | U34: 45187 | V34: 45190 | AB34: VqSwe38xRAmxh-3OI8hbKg
A35: 13623-E | B35: CR DOS SANTOS | C35: 0 | D35: 11806 | E35: AMOSTRA FT-25/40 | F35: TOUCH | G35: NAO | H35: NAO | I35: ENTREGUE | J35: EXPRESSO M.LOG | K35: SEM REDESPACHO | L35: 9725 | O35: 45195 | T35: 45187 | U35: 45187 | V35: 45194 | AB35: UlFQ9IlvQgSTs8fJH30gVg
A36: 13625 | B36: CR DOS SANTOS | C36: 0 | D36: 11793 | E36: FT160F35T | F36: TOUCH | G36: SOBREPOR | H36: NAO | I36: ENTREGUE | J36: EXPRESSO M.LOG | K36: SEM REDESPACHO | L36: 9699 | O36: 45190 | T36: 45187 | U36: 45187 | V36: 45190 | AB36: o6Kxd5G1SBm3WbEKUDVzWA
A37: 13627-A | B37: CR DOS SANTOS | C37: 137 | D37: 8B00230924003185 | E37: FTI55D40PT | F37: WI-FI | G37: NAO | H37: NAO | I37: ENTREGUE | J37: EXPRESSO M.LOG | K37: SEM REDESPACHO | L37: 9814-10249 | O37: 45309 | T37: 45187 | U37: 45306 | V37: 45309 | AB37: BTa..KDLSG-3OwZW2864TA
A38: 13627-B | B38: CR DOS SANTOS | C38: 0 | D38: 8B00230927003064 | E38: FTI75D40CZ | F38: WI-FI | G38: NAO | H38: NAO | I38: ENTREGUE | J38: EXPRESSO M.LOG | K38: SEM REDESPACHO | L38: 9814-10249 | O38: 45309 | T38: 45187 | U38: 45306 | V38: 45309 | AB38: a-5d1CQR5S2W1vugvBQGg3g
A39: 13629 | B39: ESSENCIAL CASA LAZER LTDA | C39: 0 | D39: 11166 | E39: FT60D35T | F39: TOUCH | G39: NAO | H39: NAO | I39: ENTREGUE | J39: EXPRESSO SAO MIGUEL | K39: SEM REDESPACHO | L39: 9668 | O39: 45183 | P39: VENDA PELA FROMTHERM, MAS RETIRA PELO ESTOQUE DA BOLHA AZUL ENTRADA 5MIL + 30/60 -NS 12639 -NF 9107-OP 11166 | T39: 45195 | U39: 45178 | V39: 45182 | AB39: 1S3pWmqkSRucEb88040hjg
A40: 13631 | B40: ELIANE MARIA DOS SANTOS PINHEIRO | C40: 0 | D40: 11794 | E40: FT40B35T | F40: TOUCH | G40: SOBREPOR | H40: NAO | I40: ENTREGUE | J40: DESTAK | K40: BOM JESUS | L40: 9720 | O40: 45194 | T40: 45187 | U40: 45187 | V40: 45190 | AB40: X8pmrO5dSBmNmXVnw1SWig
...

Sheet CONSULTAS
B1: CLIENTE/NOME FANTASIA | C1: QTY EM ESTOQUE | D1: ORDEM DE PROD INFOR. DE PROD. | E1: MODELO | F1: CONTROL | G1: TIPO DE QUADRO | H1: ESQ ESF | I1: SITUAÇÃO | J1: TRANSPORTADORA | K1: REDESPACHO | L1: NUMERO DA NOTA FISCAL | M1: EXPEDIDO POR | N1: VEICULO | O1: DATA DE ENTREGA | P1: OBSERVAÇÃO | Q1: INSERIDO POR | R1: APROVADO POR | S1: FINALIZADO POR | T1: INTEGRAÇÃO DO PEDIDO | U1: APROVAÇÃO PEDIDO | V1: FINALIZAÇÃO DA IDENTIFICAÇÃO | W1: 🔒 Row ID | X1: FORMA PGTO | Y1: DATA_PAGTO | Z1: VALOR | AA1: UF | AB1: REP | AC1: OBS GERAIS
A2: =IFERROR(__xludf.DUMMYFUNCTION("SORT(FILTER(PEDIDOS!A1:P547,(PEDIDOS!I1:I547=""PRODUÇÃO"")+(PEDIDOS!I1:I547=""EM ABERTO"")+(PEDIDOS!I1:I547=""PRIORIDADE"")+(PEDIDOS!I1:I547=""TESTAR"")),9,TRUE )"),"18788-B") -> 18788-B | B2: =IFERROR(__xludf.DUMMYFUNCTION("""COMPUTED_VALUE"""),"PRO LAZER") -> PRO LAZER | C2: =IFERROR(__xludf.DUMMYFUNCTION("""COMPUTED_VALUE"""),0.0) -> 0 | D2: =IFERROR(__xludf.DUMMYFUNCTION("""COMPUTED_VALUE"""),"20374") -> 20374 | E2: =IFERROR(__xludf.DUMMYFUNCTION("""COMPUTED_VALUE"""),"FTI145DPTBR") -> FTI145DPTBR | F2: =IFERROR(__xludf.DUMMYFUNCTION("""COMPUTED_VALUE"""),"WI-FI") -> WI-FI | G2: =IFERROR(__xludf.DUMMYFUNCTION("""COMPUTED_VALUE"""),"NAO") -> NAO | H2: =IFERROR(__xludf.DUMMYFUNCTION("""COMPUTED_VALUE"""),"NAO") -> NAO | I2: =IFERROR(__xludf.DUMMYFUNCTION("""COMPUTED_VALUE"""),"EM ABERTO") -> EM ABERTO | J2: =IFERROR(__xludf.DUMMYFUNCTION("""COMPUTED_VALUE"""),"MINUANO") -> MINUANO | K2: =IFERROR(__xludf.DUMMYFUNCTION("""COMPUTED_VALUE"""),"SEM REDESPACHO") -> SEM REDESPACHO | P2: =IFERROR(__xludf.DUMMYFUNCTION("""COMPUTED_VALUE"""),"EXPRESSO SAO MIGUEL S/A / (049) 3361-6627Obs.Interna: Prazo de acordo com Mario via wats app. aguardar cliente confirmar transportadora. informar prazo de entrega/ fabricação das máquinas / E-mail para nota fiscal: , E-mail de cobrança: , Telefone para c"&"ontato") -> EXPRESSO SAO MIGUEL S/A / (049) 3361-6627Obs.Interna: Prazo de acordo com Mario via wats app. aguardar cliente confirmar transportadora. informar prazo de entrega/ fabricação das máquinas / E-mail para nota fiscal: , E-mail de cobrança: , Telefone para contato
A3: =IFERROR(__xludf.DUMMYFUNCTION("""COMPUTED_VALUE"""),"18812") -> 18812 | B3: =IFERROR(__xludf.DUMMYFUNCTION("""COMPUTED_VALUE"""),"LOJA DAS PISCINAS") -> LOJA DAS PISCINAS | C3: =IFERROR(__xludf.DUMMYFUNCTION("""COMPUTED_VALUE"""),0.0) -> 0 | E3: =IFERROR(__xludf.DUMMYFUNCTION("""COMPUTED_VALUE"""),"FTI45DPTBR") -> FTI45DPTBR | F3: =IFERROR(__xludf.DUMMYFUNCTION("""COMPUTED_VALUE"""),"WI-FI") -> WI-FI | G3: =IFERROR(__xludf.DUMMYFUNCTION("""COMPUTED_VALUE"""),"NAO") -> NAO | H3: =IFERROR(__xludf.DUMMYFUNCTION("""COMPUTED_VALUE"""),"NAO") -> NAO | I3: =IFERROR(__xludf.DUMMYFUNCTION("""COMPUTED_VALUE"""),"EM ABERTO") -> EM ABERTO | J3: =IFERROR(__xludf.DUMMYFUNCTION("""COMPUTED_VALUE"""),"EXPRESSO SAO MIGUEL") -> EXPRESSO SAO MIGUEL | K3: =IFERROR(__xludf.DUMMYFUNCTION("""COMPUTED_VALUE"""),"SEM REDESPACHO") -> SEM REDESPACHO | P3: =IFERROR(__xludf.DUMMYFUNCTION("""COMPUTED_VALUE"""),"EXPRESSO SAO MIGUEL S/A / (051) 3586-2013E-mail para nota fiscal: , E-mail de cobrança: , Telefone para contato") -> EXPRESSO SAO MIGUEL S/A / (051) 3586-2013E-mail para nota fiscal: , E-mail de cobrança: , Telefone para contato
A4: =IFERROR(__xludf.DUMMYFUNCTION("""COMPUTED_VALUE"""),"18857-A") -> 18857-A | B4: =IFERROR(__xludf.DUMMYFUNCTION("""COMPUTED_VALUE"""),"CASA DA PISCINA MATO GROSSO") -> CASA DA PISCINA MATO GROSSO | C4: =IFERROR(__xludf.DUMMYFUNCTION("""COMPUTED_VALUE"""),0.0) -> 0 | E4: =IFERROR(__xludf.DUMMYFUNCTION("""COMPUTED_VALUE"""),"FH40B60T") -> FH40B60T | F4: =IFERROR(__xludf.DUMMYFUNCTION("""COMPUTED_VALUE"""),"TOUCH") -> TOUCH | G4: =IFERROR(__xludf.DUMMYFUNCTION("""COMPUTED_VALUE"""),"SOBREPOR") -> SOBREPOR | H4: =IFERROR(__xludf.DUMMYFUNCTION("""COMPUTED_VALUE"""),"NAO") -> NAO | I4: =IFERROR(__xludf.DUMMYFUNCTION("""COMPUTED_VALUE"""),"EM ABERTO") -> EM ABERTO | J4: =IFERROR(__xludf.DUMMYFUNCTION("""COMPUTED_VALUE"""),"RODONAVES") -> RODONAVES | K4: =IFERROR(__xludf.DUMMYFUNCTION("""COMPUTED_VALUE"""),"SEM REDESPACHO") -> SEM REDESPACHO | P4: =IFERROR(__xludf.DUMMYFUNCTION("""COMPUTED_VALUE"""),"EXPRESSO SAO MIGUEL S/A / (051) 3586-2013Informação Adicional: TRANSPORTADORA: PICCOLI TRANSPORTES- CNPJ 01.496.359/0002-45 - Rua Viela Urga-nº557 -Bairro Vila Nova Bonsucesso- Guarulhos -cep 07175-332 SP - 1139880170 / Obs.Interna: AVISAR PRODUÇÃO- QUAD"&"RO DESLOCADO . / E-mail para nota fiscal: , E-mail de cobrança: , Telefone para contato") -> EXPRESSO SAO MIGUEL S/A / (051) 3586-2013Informação Adicional: TRANSPORTADORA: PICCOLI TRANSPORTES- CNPJ 01.496.359/0002-45 - Rua Viela Urga-nº557 -Bairro Vila Nova Bonsucesso- Guarulhos -cep 07175-332 SP - 1139880170 / Obs.Interna: AVISAR PRODUÇÃO- QUADRO DESLOCADO . / E-mail para nota fiscal: , E-mail de cobrança: , Telefone para contato
A5: =IFERROR(__xludf.DUMMYFUNCTION("""COMPUTED_VALUE"""),"18857-B") -> 18857-B | B5: =IFERROR(__xludf.DUMMYFUNCTION("""COMPUTED_VALUE"""),"CASA DA PISCINA MATO GROSSO") -> CASA DA PISCINA MATO GROSSO | C5: =IFERROR(__xludf.DUMMYFUNCTION("""COMPUTED_VALUE"""),0.0) -> 0 | D5: =IFERROR(__xludf.DUMMYFUNCTION("""COMPUTED_VALUE"""),20435.0) -> 20435 | E5: =IFERROR(__xludf.DUMMYFUNCTION("""COMPUTED_VALUE"""),"FH80B60T") -> FH80B60T | F5: =IFERROR(__xludf.DUMMYFUNCTION("""COMPUTED_VALUE"""),"TOUCH") -> TOUCH | G5: =IFERROR(__xludf.DUMMYFUNCTION("""COMPUTED_VALUE"""),"SOBREPOR") -> SOBREPOR | H5: =IFERROR(__xludf.DUMMYFUNCTION("""COMPUTED_VALUE"""),"NAO") -> NAO | I5: =IFERROR(__xludf.DUMMYFUNCTION("""COMPUTED_VALUE"""),"EM ABERTO") -> EM ABERTO | J5: =IFERROR(__xludf.DUMMYFUNCTION("""COMPUTED_VALUE"""),"RODONAVES") -> RODONAVES | K5: =IFERROR(__xludf.DUMMYFUNCTION("""COMPUTED_VALUE"""),"SEM REDESPACHO") -> SEM REDESPACHO | P5: =IFERROR(__xludf.DUMMYFUNCTION("""COMPUTED_VALUE"""),"EXPRESSO SAO MIGUEL S/A / (051) 3586-2013Informação Adicional: TRANSPORTADORA: PICCOLI TRANSPORTES- CNPJ 01.496.359/0002-45 - Rua Viela Urga-nº557 -Bairro Vila Nova Bonsucesso- Guarulhos -cep 07175-332 SP - 1139880170 / Obs.Interna: AVISAR PRODUÇÃO- QUAD"&"RO DESLOCADO . / E-mail para nota fiscal: , E-mail de cobrança: , Telefone para contato") -> EXPRESSO SAO MIGUEL S/A / (051) 3586-2013Informação Adicional: TRANSPORTADORA: PICCOLI TRANSPORTES- CNPJ 01.496.359/0002-45 - Rua Viela Urga-nº557 -Bairro Vila Nova Bonsucesso- Guarulhos -cep 07175-332 SP - 1139880170 / Obs.Interna: AVISAR PRODUÇÃO- QUADRO DESLOCADO . / E-mail para nota fiscal: , E-mail de cobrança: , Telefone para contato
A6: =IFERROR(__xludf.DUMMYFUNCTION("""COMPUTED_VALUE"""),"18859") -> 18859 | B6: =IFERROR(__xludf.DUMMYFUNCTION("""COMPUTED_VALUE"""),"AQUAVIL PISCINAS LTDA") -> AQUAVIL PISCINAS LTDA | C6: =IFERROR(__xludf.DUMMYFUNCTION("""COMPUTED_VALUE"""),0.0) -> 0 | D6: =IFERROR(__xludf.DUMMYFUNCTION("""COMPUTED_VALUE"""),"20373") -> 20373 | E6: =IFERROR(__xludf.DUMMYFUNCTION("""COMPUTED_VALUE"""),"FTI145DPTBR") -> FTI145DPTBR | F6: =IFERROR(__xludf.DUMMYFUNCTION("""COMPUTED_VALUE"""),"WI-FI") -> WI-FI | G6: =IFERROR(__xludf.DUMMYFUNCTION("""COMPUTED_VALUE"""),"NAO") -> NAO | H6: =IFERROR(__xludf.DUMMYFUNCTION("""COMPUTED_VALUE"""),"NAO") -> NAO | I6: =IFERROR(__xludf.DUMMYFUNCTION("""COMPUTED_VALUE"""),"EM ABERTO") -> EM ABERTO | J6: =IFERROR(__xludf.DUMMYFUNCTION("""COMPUTED_VALUE"""),"FITLOG") -> FITLOG | K6: =IFERROR(__xludf.DUMMYFUNCTION("""COMPUTED_VALUE"""),"SEM REDESPACHO") -> SEM REDESPACHO | P6: =IFERROR(__xludf.DUMMYFUNCTION("""COMPUTED_VALUE"""),"FITLOG TRANSPORTES E LOGISTICA LTDA / (048) 996277956E-mail para nota fiscal: , E-mail de cobrança: , Telefone para contato") -> FITLOG TRANSPORTES E LOGISTICA LTDA / (048) 996277956E-mail para nota fiscal: , E-mail de cobrança: , Telefone para contato
A7: =IFERROR(__xludf.DUMMYFUNCTION("""COMPUTED_VALUE"""),"18862") -> 18862 | B7: =IFERROR(__xludf.DUMMYFUNCTION("""COMPUTED_VALUE"""),"2 CORACOES PISCINAS E DECORACOES") -> 2 CORACOES PISCINAS E DECORACOES | C7: =IFERROR(__xludf.DUMMYFUNCTION("""COMPUTED_VALUE"""),0.0) -> 0 | E7: =IFERROR(__xludf.DUMMYFUNCTION("""COMPUTED_VALUE"""),"FTI45DPTBR") -> FTI45DPTBR | F7: =IFERROR(__xludf.DUMMYFUNCTION("""COMPUTED_VALUE"""),"WI-FI") -> WI-FI | G7: =IFERROR(__xludf.DUMMYFUNCTION("""COMPUTED_VALUE"""),"NAO") -> NAO | H7: =IFERROR(__xludf.DUMMYFUNCTION("""COMPUTED_VALUE"""),"NAO") -> NAO | I7: =IFERROR(__xludf.DUMMYFUNCTION("""COMPUTED_VALUE"""),"EM ABERTO") -> EM ABERTO | J7: =IFERROR(__xludf.DUMMYFUNCTION("""COMPUTED_VALUE"""),"EXPRESSO SAO MIGUEL") -> EXPRESSO SAO MIGUEL | K7: =IFERROR(__xludf.DUMMYFUNCTION("""COMPUTED_VALUE"""),"SEM REDESPACHO") -> SEM REDESPACHO | P7: =IFERROR(__xludf.DUMMYFUNCTION("""COMPUTED_VALUE"""),"EXPRESSO SAO MIGUEL S/A / (051) 3586-2013E-mail para nota fiscal: , E-mail de cobrança: , Telefone para contato") -> EXPRESSO SAO MIGUEL S/A / (051) 3586-2013E-mail para nota fiscal: , E-mail de cobrança: , Telefone para contato
A8: =IFERROR(__xludf.DUMMYFUNCTION("""COMPUTED_VALUE"""),"18867-A") -> 18867-A | B8: =IFERROR(__xludf.DUMMYFUNCTION("""COMPUTED_VALUE"""),"DJA COMERCIO DE PISCINAS LTDA - ME") -> DJA COMERCIO DE PISCINAS LTDA - ME | C8: =IFERROR(__xludf.DUMMYFUNCTION("""COMPUTED_VALUE"""),0.0) -> 0 | E8: =IFERROR(__xludf.DUMMYFUNCTION("""COMPUTED_VALUE"""),"FTI145DPTBR") -> FTI145DPTBR | F8: =IFERROR(__xludf.DUMMYFUNCTION("""COMPUTED_VALUE"""),"WI-FI") -> WI-FI | G8: =IFERROR(__xludf.DUMMYFUNCTION("""COMPUTED_VALUE"""),"NAO") -> NAO | H8: =IFERROR(__xludf.DUMMYFUNCTION("""COMPUTED_VALUE"""),"NAO") -> NAO | I8: =IFERROR(__xludf.DUMMYFUNCTION("""COMPUTED_VALUE"""),"EM ABERTO") -> EM ABERTO | J8: =IFERROR(__xludf.DUMMYFUNCTION("""COMPUTED_VALUE"""),"FITLOG") -> FITLOG | K8: =IFERROR(__xludf.DUMMYFUNCTION("""COMPUTED_VALUE"""),"SEM REDESPACHO") -> SEM REDESPACHO | P8: =IFERROR(__xludf.DUMMYFUNCTION("""COMPUTED_VALUE"""),"FITLOG TRANSPORTES E LOGISTICA LTDA / (048) 996277956Informação Adicional: Frete CIF / E-mail para nota fiscal: , E-mail de cobrança: , Telefone para contato") -> FITLOG TRANSPORTES E LOGISTICA LTDA / (048) 996277956Informação Adicional: Frete CIF / E-mail para nota fiscal: , E-mail de cobrança: , Telefone para contato
A9: =IFERROR(__xludf.DUMMYFUNCTION("""COMPUTED_VALUE"""),"18867-B") -> 18867-B | B9: =IFERROR(__xludf.DUMMYFUNCTION("""COMPUTED_VALUE"""),"DJA COMERCIO DE PISCINAS LTDA - ME") -> DJA COMERCIO DE PISCINAS LTDA - ME | C9: =IFERROR(__xludf.DUMMYFUNCTION("""COMPUTED_VALUE"""),0.0) -> 0 | E9: =IFERROR(__xludf.DUMMYFUNCTION("""COMPUTED_VALUE"""),"FTI145DPTBR") -> FTI145DPTBR | F9: =IFERROR(__xludf.DUMMYFUNCTION("""COMPUTED_VALUE"""),"WI-FI") -> WI-FI | G9: =IFERROR(__xludf.DUMMYFUNCTION("""COMPUTED_VALUE"""),"NAO") -> NAO | H9: =IFERROR(__xludf.DUMMYFUNCTION("""COMPUTED_VALUE"""),"NAO") -> NAO | I9: =IFERROR(__xludf.DUMMYFUNCTION("""COMPUTED_VALUE"""),"EM ABERTO") -> EM ABERTO | J9: =IFERROR(__xludf.DUMMYFUNCTION("""COMPUTED_VALUE"""),"FITLOG") -> FITLOG | K9: =IFERROR(__xludf.DUMMYFUNCTION("""COMPUTED_VALUE"""),"SEM REDESPACHO") -> SEM REDESPACHO | P9: =IFERROR(__xludf.DUMMYFUNCTION("""COMPUTED_VALUE"""),"FITLOG TRANSPORTES E LOGISTICA LTDA / (048) 996277956Informação Adicional: Frete CIF / E-mail para nota fiscal: , E-mail de cobrança: , Telefone para contato") -> FITLOG TRANSPORTES E LOGISTICA LTDA / (048) 996277956Informação Adicional: Frete CIF / E-mail para nota fiscal: , E-mail de cobrança: , Telefone para contato
A10: =IFERROR(__xludf.DUMMYFUNCTION("""COMPUTED_VALUE"""),"18871-B") -> 18871-B | B10: =IFERROR(__xludf.DUMMYFUNCTION("""COMPUTED_VALUE"""),"STEINFIBER") -> STEINFIBER | C10: =IFERROR(__xludf.DUMMYFUNCTION("""COMPUTED_VALUE"""),0.0) -> 0 | E10: =IFERROR(__xludf.DUMMYFUNCTION("""COMPUTED_VALUE"""),"FTI145LPTBR") -> FTI145LPTBR | F10: =IFERROR(__xludf.DUMMYFUNCTION("""COMPUTED_VALUE"""),"WI-FI") -> WI-FI | G10: =IFERROR(__xludf.DUMMYFUNCTION("""COMPUTED_VALUE"""),"NAO") -> NAO | H10: =IFERROR(__xludf.DUMMYFUNCTION("""COMPUTED_VALUE"""),"NAO") -> NAO | I10: =IFERROR(__xludf.DUMMYFUNCTION("""COMPUTED_VALUE"""),"EM ABERTO") -> EM ABERTO | J10: =IFERROR(__xludf.DUMMYFUNCTION("""COMPUTED_VALUE"""),"RETIRA") -> RETIRA | K10: =IFERROR(__xludf.DUMMYFUNCTION("""COMPUTED_VALUE"""),"SEM REDESPACHO") -> SEM REDESPACHO | P10: =IFERROR(__xludf.DUMMYFUNCTION("""COMPUTED_VALUE"""),"CLIENTE RETIRA / (0) Informação Adicional: PREÇO NEGOCIADO R$ 18.600,00 - ALTERAR NO PEDIDO - AUTORIZADO POR PRISCILLA ENTREGA: 01 MÁQUINA DIA 20/10 E AS OUTRAS 06 MAXIMO DIA 05/11 / E-mail para nota fiscal: , E-mail de cobrança: , Telefone para contat"&"o") -> CLIENTE RETIRA / (0) Informação Adicional: PREÇO NEGOCIADO R$ 18.600,00 - ALTERAR NO PEDIDO - AUTORIZADO POR PRISCILLA ENTREGA: 01 MÁQUINA DIA 20/10 E AS OUTRAS 06 MAXIMO DIA 05/11 / E-mail para nota fiscal: , E-mail de cobrança: , Telefone para contato
A11: =IFERROR(__xludf.DUMMYFUNCTION("""COMPUTED_VALUE"""),"18871-C") -> 18871-C | B11: =IFERROR(__xludf.DUMMYFUNCTION("""COMPUTED_VALUE"""),"STEINFIBER") -> STEINFIBER | C11: =IFERROR(__xludf.DUMMYFUNCTION("""COMPUTED_VALUE"""),0.0) -> 0 | E11: =IFERROR(__xludf.DUMMYFUNCTION("""COMPUTED_VALUE"""),"FTI145LPTBR") -> FTI145LPTBR | F11: =IFERROR(__xludf.DUMMYFUNCTION("""COMPUTED_VALUE"""),"WI-FI") -> WI-FI | G11: =IFERROR(__xludf.DUMMYFUNCTION("""COMPUTED_VALUE"""),"NAO") -> NAO | H11: =IFERROR(__xludf.DUMMYFUNCTION("""COMPUTED_VALUE"""),"NAO") -> NAO | I11: =IFERROR(__xludf.DUMMYFUNCTION("""COMPUTED_VALUE"""),"EM ABERTO") -> EM ABERTO | J11: =IFERROR(__xludf.DUMMYFUNCTION("""COMPUTED_VALUE"""),"RETIRA") -> RETIRA | K11: =IFERROR(__xludf.DUMMYFUNCTION("""COMPUTED_VALUE"""),"SEM REDESPACHO") -> SEM REDESPACHO | P11: =IFERROR(__xludf.DUMMYFUNCTION("""COMPUTED_VALUE"""),"CLIENTE RETIRA / (0) Informação Adicional: PREÇO NEGOCIADO R$ 18.600,00 - ALTERAR NO PEDIDO - AUTORIZADO POR PRISCILLA ENTREGA: 01 MÁQUINA DIA 20/10 E AS OUTRAS 06 MAXIMO DIA 05/11 / E-mail para nota fiscal: , E-mail de cobrança: , Telefone para contat"&"o") -> CLIENTE RETIRA / (0) Informação Adicional: PREÇO NEGOCIADO R$ 18.600,00 - ALTERAR NO PEDIDO - AUTORIZADO POR PRISCILLA ENTREGA: 01 MÁQUINA DIA 20/10 E AS OUTRAS 06 MAXIMO DIA 05/11 / E-mail para nota fiscal: , E-mail de cobrança: , Telefone para contato
A12: =IFERROR(__xludf.DUMMYFUNCTION("""COMPUTED_VALUE"""),"18871-D") -> 18871-D | B12: =IFERROR(__xludf.DUMMYFUNCTION("""COMPUTED_VALUE"""),"STEINFIBER") -> STEINFIBER | C12: =IFERROR(__xludf.DUMMYFUNCTION("""COMPUTED_VALUE"""),0.0) -> 0 | E12: =IFERROR(__xludf.DUMMYFUNCTION("""COMPUTED_VALUE"""),"FTI145LPTBR") -> FTI145LPTBR | F12: =IFERROR(__xludf.DUMMYFUNCTION("""COMPUTED_VALUE"""),"WI-FI") -> WI-FI | G12: =IFERROR(__xludf.DUMMYFUNCTION("""COMPUTED_VALUE"""),"NAO") -> NAO | H12: =IFERROR(__xludf.DUMMYFUNCTION("""COMPUTED_VALUE"""),"NAO") -> NAO | I12: =IFERROR(__xludf.DUMMYFUNCTION("""COMPUTED_VALUE"""),"EM ABERTO") -> EM ABERTO | J12: =IFERROR(__xludf.DUMMYFUNCTION("""COMPUTED_VALUE"""),"RETIRA") -> RETIRA | K12: =IFERROR(__xludf.DUMMYFUNCTION("""COMPUTED_VALUE"""),"SEM REDESPACHO") -> SEM REDESPACHO | P12: =IFERROR(__xludf.DUMMYFUNCTION("""COMPUTED_VALUE"""),"CLIENTE RETIRA / (0) Informação Adicional: PREÇO NEGOCIADO R$ 18.600,00 - ALTERAR NO PEDIDO - AUTORIZADO POR PRISCILLA ENTREGA: 01 MÁQUINA DIA 20/10 E AS OUTRAS 06 MAXIMO DIA 05/11 / E-mail para nota fiscal: , E-mail de cobrança: , Telefone para contat"&"o") -> CLIENTE RETIRA / (0) Informação Adicional: PREÇO NEGOCIADO R$ 18.600,00 - ALTERAR NO PEDIDO - AUTORIZADO POR PRISCILLA ENTREGA: 01 MÁQUINA DIA 20/10 E AS OUTRAS 06 MAXIMO DIA 05/11 / E-mail para nota fiscal: , E-mail de cobrança: , Telefone para contato
A13: =IFERROR(__xludf.DUMMYFUNCTION("""COMPUTED_VALUE"""),"18871-E") -> 18871-E | B13: =IFERROR(__xludf.DUMMYFUNCTION("""COMPUTED_VALUE"""),"STEINFIBER") -> STEINFIBER | C13: =IFERROR(__xludf.DUMMYFUNCTION("""COMPUTED_VALUE"""),0.0) -> 0 | E13: =IFERROR(__xludf.DUMMYFUNCTION("""COMPUTED_VALUE"""),"FTI145LPTBR") -> FTI145LPTBR | F13: =IFERROR(__xludf.DUMMYFUNCTION("""COMPUTED_VALUE"""),"WI-FI") -> WI-FI | G13: =IFERROR(__xludf.DUMMYFUNCTION("""COMPUTED_VALUE"""),"NAO") -> NAO | H13: =IFERROR(__xludf.DUMMYFUNCTION("""COMPUTED_VALUE"""),"NAO") -> NAO | I13: =IFERROR(__xludf.DUMMYFUNCTION("""COMPUTED_VALUE"""),"EM ABERTO") -> EM ABERTO | J13: =IFERROR(__xludf.DUMMYFUNCTION("""COMPUTED_VALUE"""),"RETIRA") -> RETIRA | K13: =IFERROR(__xludf.DUMMYFUNCTION("""COMPUTED_VALUE"""),"SEM REDESPACHO") -> SEM REDESPACHO | P13: =IFERROR(__xludf.DUMMYFUNCTION("""COMPUTED_VALUE"""),"CLIENTE RETIRA / (0) Informação Adicional: PREÇO NEGOCIADO R$ 18.600,00 - ALTERAR NO PEDIDO - AUTORIZADO POR PRISCILLA ENTREGA: 01 MÁQUINA DIA 20/10 E AS OUTRAS 06 MAXIMO DIA 05/11 / E-mail para nota fiscal: , E-mail de cobrança: , Telefone para contat"&"o") -> CLIENTE RETIRA / (0) Informação Adicional: PREÇO NEGOCIADO R$ 18.600,00 - ALTERAR NO PEDIDO - AUTORIZADO POR PRISCILLA ENTREGA: 01 MÁQUINA DIA 20/10 E AS OUTRAS 06 MAXIMO DIA 05/11 / E-mail para nota fiscal: , E-mail de cobrança: , Telefone para contato
A14: =IFERROR(__xludf.DUMMYFUNCTION("""COMPUTED_VALUE"""),"18871-F") -> 18871-F | B14: =IFERROR(__xludf.DUMMYFUNCTION("""COMPUTED_VALUE"""),"STEINFIBER") -> STEINFIBER | C14: =IFERROR(__xludf.DUMMYFUNCTION("""COMPUTED_VALUE"""),0.0) -> 0 | E14: =IFERROR(__xludf.DUMMYFUNCTION("""COMPUTED_VALUE"""),"FTI145LPTBR") -> FTI145LPTBR | F14: =IFERROR(__xludf.DUMMYFUNCTION("""COMPUTED_VALUE"""),"WI-FI") -> WI-FI | G14: =IFERROR(__xludf.DUMMYFUNCTION("""COMPUTED_VALUE"""),"NAO") -> NAO | H14: =IFERROR(__xludf.DUMMYFUNCTION("""COMPUTED_VALUE"""),"NAO") -> NAO | I14: =IFERROR(__xludf.DUMMYFUNCTION("""COMPUTED_VALUE"""),"EM ABERTO") -> EM ABERTO | J14: =IFERROR(__xludf.DUMMYFUNCTION("""COMPUTED_VALUE"""),"RETIRA") -> RETIRA | K14: =IFERROR(__xludf.DUMMYFUNCTION("""COMPUTED_VALUE"""),"SEM REDESPACHO") -> SEM REDESPACHO | P14: =IFERROR(__xludf.DUMMYFUNCTION("""COMPUTED_VALUE"""),"CLIENTE RETIRA / (0) Informação Adicional: PREÇO NEGOCIADO R$ 18.600,00 - ALTERAR NO PEDIDO - AUTORIZADO POR PRISCILLA ENTREGA: 01 MÁQUINA DIA 20/10 E AS OUTRAS 06 MAXIMO DIA 05/11 / E-mail para nota fiscal: , E-mail de cobrança: , Telefone para contat"&"o") -> CLIENTE RETIRA / (0) Informação Adicional: PREÇO NEGOCIADO R$ 18.600,00 - ALTERAR NO PEDIDO - AUTORIZADO POR PRISCILLA ENTREGA: 01 MÁQUINA DIA 20/10 E AS OUTRAS 06 MAXIMO DIA 05/11 / E-mail para nota fiscal: , E-mail de cobrança: , Telefone para contato
A15: =IFERROR(__xludf.DUMMYFUNCTION("""COMPUTED_VALUE"""),"18871-G") -> 18871-G | B15: =IFERROR(__xludf.DUMMYFUNCTION("""COMPUTED_VALUE"""),"STEINFIBER") -> STEINFIBER | C15: =IFERROR(__xludf.DUMMYFUNCTION("""COMPUTED_VALUE"""),0.0) -> 0 | E15: =IFERROR(__xludf.DUMMYFUNCTION("""COMPUTED_VALUE"""),"FTI145LPTBR") -> FTI145LPTBR | F15: =IFERROR(__xludf.DUMMYFUNCTION("""COMPUTED_VALUE"""),"WI-FI") -> WI-FI | G15: =IFERROR(__xludf.DUMMYFUNCTION("""COMPUTED_VALUE"""),"NAO") -> NAO | H15: =IFERROR(__xludf.DUMMYFUNCTION("""COMPUTED_VALUE"""),"NAO") -> NAO | I15: =IFERROR(__xludf.DUMMYFUNCTION("""COMPUTED_VALUE"""),"EM ABERTO") -> EM ABERTO | J15: =IFERROR(__xludf.DUMMYFUNCTION("""COMPUTED_VALUE"""),"RETIRA") -> RETIRA | K15: =IFERROR(__xludf.DUMMYFUNCTION("""COMPUTED_VALUE"""),"SEM REDESPACHO") -> SEM REDESPACHO | P15: =IFERROR(__xludf.DUMMYFUNCTION("""COMPUTED_VALUE"""),"CLIENTE RETIRA / (0) Informação Adicional: PREÇO NEGOCIADO R$ 18.600,00 - ALTERAR NO PEDIDO - AUTORIZADO POR PRISCILLA ENTREGA: 01 MÁQUINA DIA 20/10 E AS OUTRAS 06 MAXIMO DIA 05/11 / E-mail para nota fiscal: , E-mail de cobrança: , Telefone para contat"&"o") -> CLIENTE RETIRA / (0) Informação Adicional: PREÇO NEGOCIADO R$ 18.600,00 - ALTERAR NO PEDIDO - AUTORIZADO POR PRISCILLA ENTREGA: 01 MÁQUINA DIA 20/10 E AS OUTRAS 06 MAXIMO DIA 05/11 / E-mail para nota fiscal: , E-mail de cobrança: , Telefone para contato
A16: =IFERROR(__xludf.DUMMYFUNCTION("""COMPUTED_VALUE"""),"18886") -> 18886 | B16: =IFERROR(__xludf.DUMMYFUNCTION("""COMPUTED_VALUE"""),"VITAL PISCINAS") -> VITAL PISCINAS | C16: =IFERROR(__xludf.DUMMYFUNCTION("""COMPUTED_VALUE"""),0.0) -> 0 | D16: =IFERROR(__xludf.DUMMYFUNCTION("""COMPUTED_VALUE"""),20375.0) -> 20375 | E16: =IFERROR(__xludf.DUMMYFUNCTION("""COMPUTED_VALUE"""),"FTI145DPTBR") -> FTI145DPTBR | F16: =IFERROR(__xludf.DUMMYFUNCTION("""COMPUTED_VALUE"""),"WI-FI") -> WI-FI | G16: =IFERROR(__xludf.DUMMYFUNCTION("""COMPUTED_VALUE"""),"NAO") -> NAO | H16: =IFERROR(__xludf.DUMMYFUNCTION("""COMPUTED_VALUE"""),"NAO") -> NAO | I16: =IFERROR(__xludf.DUMMYFUNCTION("""COMPUTED_VALUE"""),"EM ABERTO") -> EM ABERTO | J16: =IFERROR(__xludf.DUMMYFUNCTION("""COMPUTED_VALUE"""),"ACEVILLE") -> ACEVILLE | K16: =IFERROR(__xludf.DUMMYFUNCTION("""COMPUTED_VALUE"""),"SEM REDESPACHO") -> SEM REDESPACHO | P16: =IFERROR(__xludf.DUMMYFUNCTION("""COMPUTED_VALUE"""),"ACEVILLE TRANSPORTES LTDA / (048) 99823-5770E-mail para nota fiscal: , E-mail de cobrança: , Telefone para contato") -> ACEVILLE TRANSPORTES LTDA / (048) 99823-5770E-mail para nota fiscal: , E-mail de cobrança: , Telefone para contato
A17: =IFERROR(__xludf.DUMMYFUNCTION("""COMPUTED_VALUE"""),"18911") -> 18911 | B17: =IFERROR(__xludf.DUMMYFUNCTION("""COMPUTED_VALUE"""),"DEPOSITO BEIRA RIO") -> DEPOSITO BEIRA RIO | C17: =IFERROR(__xludf.DUMMYFUNCTION("""COMPUTED_VALUE"""),0.0) -> 0 | E17: =IFERROR(__xludf.DUMMYFUNCTION("""COMPUTED_VALUE"""),"FTI45DPTBR") -> FTI45DPTBR | F17: =IFERROR(__xludf.DUMMYFUNCTION("""COMPUTED_VALUE"""),"WI-FI") -> WI-FI | G17: =IFERROR(__xludf.DUMMYFUNCTION("""COMPUTED_VALUE"""),"NAO") -> NAO | H17: =IFERROR(__xludf.DUMMYFUNCTION("""COMPUTED_VALUE"""),"NAO") -> NAO | I17: =IFERROR(__xludf.DUMMYFUNCTION("""COMPUTED_VALUE"""),"EM ABERTO") -> EM ABERTO | J17: =IFERROR(__xludf.DUMMYFUNCTION("""COMPUTED_VALUE"""),"RODONAVES") -> RODONAVES | K17: =IFERROR(__xludf.DUMMYFUNCTION("""COMPUTED_VALUE"""),"SEM REDESPACHO") -> SEM REDESPACHO | P17: =IFERROR(__xludf.DUMMYFUNCTION("""COMPUTED_VALUE"""),"Pedido gerado através do PedidoEletronico.com - Transportadora / telefone: RODONAVES TRANSPORTES E ENCOMENDAS LTDA / (016) 3965-2141E-mail para nota fiscal: , E-mail de cobrança: , Telefone para contato") -> Pedido gerado através do PedidoEletronico.com - Transportadora / telefone: RODONAVES TRANSPORTES E ENCOMENDAS LTDA / (016) 3965-2141E-mail para nota fiscal: , E-mail de cobrança: , Telefone para contato
A18: =IFERROR(__xludf.DUMMYFUNCTION("""COMPUTED_VALUE"""),"18923-A") -> 18923-A | B18: =IFERROR(__xludf.DUMMYFUNCTION("""COMPUTED_VALUE"""),"HYDRONIC SOLUTIONS") -> HYDRONIC SOLUTIONS | C18: =IFERROR(__xludf.DUMMYFUNCTION("""COMPUTED_VALUE"""),0.0) -> 0 | E18: =IFERROR(__xludf.DUMMYFUNCTION("""COMPUTED_VALUE"""),"FH80F60W") -> FH80F60W | G18: =IFERROR(__xludf.DUMMYFUNCTION("""COMPUTED_VALUE"""),"NAO") -> NAO | H18: =IFERROR(__xludf.DUMMYFUNCTION("""COMPUTED_VALUE"""),"NAO") -> NAO | I18: =IFERROR(__xludf.DUMMYFUNCTION("""COMPUTED_VALUE"""),"EM ABERTO") -> EM ABERTO | J18: =IFERROR(__xludf.DUMMYFUNCTION("""COMPUTED_VALUE"""),"FITLOG") -> FITLOG | K18: =IFERROR(__xludf.DUMMYFUNCTION("""COMPUTED_VALUE"""),"SEM REDESPACHO") -> SEM REDESPACHO | P18: =IFERROR(__xludf.DUMMYFUNCTION("""COMPUTED_VALUE"""),"Pedido gerado através do PedidoEletronico.com - Transportadora / telefone: FITLOG TRANSPORTES E LOGISTICA LTDA / (048) 996277956Obs.Interna: entrega futura. Entregar hotel BIARRITZ COPACABANA Rua Aires Saldanha 54 Copacabana cep 22440 032 RJ . Maquinas "&"ja implantadas anteriormente. Pedido para correção de endereço de entrega . Ligar para o Luiz antes de entregar 21 9 6518 9999 / E-mail para nota fiscal: , E-mail de cobrança: , Telefone para contato") -> Pedido gerado através do PedidoEletronico.com - Transportadora / telefone: FITLOG TRANSPORTES E LOGISTICA LTDA / (048) 996277956Obs.Interna: entrega futura. Entregar hotel BIARRITZ COPACABANA Rua Aires Saldanha 54 Copacabana cep 22440 032 RJ . Maquinas ja implantadas anteriormente. Pedido para correção de endereço de entrega . Ligar para o Luiz antes de entregar 21 9 6518 9999 / E-mail para nota fiscal: , E-mail de cobrança: , Telefone para contato
A19: =IFERROR(__xludf.DUMMYFUNCTION("""COMPUTED_VALUE"""),"18932-A") -> 18932-A | B19: =IFERROR(__xludf.DUMMYFUNCTION("""COMPUTED_VALUE"""),"INFRAH ENGENHARIA , INSTALACOES E SISTEMAS DE AQUECIMENTO LTDA") -> INFRAH ENGENHARIA , INSTALACOES E SISTEMAS DE AQUECIMENTO LTDA | C19: =IFERROR(__xludf.DUMMYFUNCTION("""COMPUTED_VALUE"""),0.0) -> 0 | E19: =IFERROR(__xludf.DUMMYFUNCTION("""COMPUTED_VALUE"""),"FH160L60T") -> FH160L60T | F19: =IFERROR(__xludf.DUMMYFUNCTION("""COMPUTED_VALUE"""),"TOUCH") -> TOUCH | G19: =IFERROR(__xludf.DUMMYFUNCTION("""COMPUTED_VALUE"""),"NAO") -> NAO | H19: =IFERROR(__xludf.DUMMYFUNCTION("""COMPUTED_VALUE"""),"NAO") -> NAO | I19: =IFERROR(__xludf.DUMMYFUNCTION("""COMPUTED_VALUE"""),"EM ABERTO") -> EM ABERTO | J19: =IFERROR(__xludf.DUMMYFUNCTION("""COMPUTED_VALUE"""),"FITLOG") -> FITLOG | K19: =IFERROR(__xludf.DUMMYFUNCTION("""COMPUTED_VALUE"""),"SEM REDESPACHO") -> SEM REDESPACHO | P19: =IFERROR(__xludf.DUMMYFUNCTION("""COMPUTED_VALUE"""),"Pedido reprocessado ao alterar dados do cliente 21/10/2025 14:08:08 usuário: P000697112 ABATER O VALOR DE R$ 60.000,00 DA COMISSÃO QUE A INFRAH TEM A RECEBER DO HOTEL VILLA LOBOS E PARCELAR O RESTANTE. CONVERSAR COM A PRISCILLA, POIS ESSE PEDIDO SAIRÁ CO"&"M UM VALOR DE NF. MENOR. Pedido gerado através do PedidoEletronico.com - Transportadora / telefone: FITLOG TRANSPORTES E LOGISTICA LTDA / (048) 996277956Informação Adicional: ENDEREÇO DE ENTREGA: HOTEL ÍBIS BUDGET PAULISTA - RUA DA CONSOLAÇÃO, 2.303 - CO"&"NSOLAÇÃO - SÃO PAULO - SP - CEP: 01301-100, LIGAR PARA O ALISSON ANTES DE ENTREGAR - (11) 9 9473 5150. / E-mail para nota fiscal: , E-mail de cobrança: , Telefone para contato") -> Pedido reprocessado ao alterar dados do cliente 21/10/2025 14:08:08 usuário: P000697112 ABATER O VALOR DE R$ 60.000,00 DA COMISSÃO QUE A INFRAH TEM A RECEBER DO HOTEL VILLA LOBOS E PARCELAR O RESTANTE. CONVERSAR COM A PRISCILLA, POIS ESSE PEDIDO SAIRÁ COM UM VALOR DE NF. MENOR. Pedido gerado através do PedidoEletronico.com - Transportadora / telefone: FITLOG TRANSPORTES E LOGISTICA LTDA / (048) 996277956Informação Adicional: ENDEREÇO DE ENTREGA: HOTEL ÍBIS BUDGET PAULISTA - RUA DA CONSOLAÇÃO, 2.303 - CONSOLAÇÃO - SÃO PAULO - SP - CEP: 01301-100, LIGAR PARA O ALISSON ANTES DE ENTREGAR - (11) 9 9473 5150. / E-mail para nota fiscal: , E-mail de cobrança: , Telefone para contato
A20: =IFERROR(__xludf.DUMMYFUNCTION("""COMPUTED_VALUE"""),"18932-B") -> 18932-B | B20: =IFERROR(__xludf.DUMMYFUNCTION("""COMPUTED_VALUE"""),"INFRAH ENGENHARIA , INSTALACOES E SISTEMAS DE AQUECIMENTO LTDA") -> INFRAH ENGENHARIA , INSTALACOES E SISTEMAS DE AQUECIMENTO LTDA | C20: =IFERROR(__xludf.DUMMYFUNCTION("""COMPUTED_VALUE"""),0.0) -> 0 | E20: =IFERROR(__xludf.DUMMYFUNCTION("""COMPUTED_VALUE"""),"FH160L60T") -> FH160L60T | F20: =IFERROR(__xludf.DUMMYFUNCTION("""COMPUTED_VALUE"""),"TOUCH") -> TOUCH | G20: =IFERROR(__xludf.DUMMYFUNCTION("""COMPUTED_VALUE"""),"NAO") -> NAO | H20: =IFERROR(__xludf.DUMMYFUNCTION("""COMPUTED_VALUE"""),"NAO") -> NAO | I20: =IFERROR(__xludf.DUMMYFUNCTION("""COMPUTED_VALUE"""),"EM ABERTO") -> EM ABERTO | J20: =IFERROR(__xludf.DUMMYFUNCTION("""COMPUTED_VALUE"""),"FITLOG") -> FITLOG | K20: =IFERROR(__xludf.DUMMYFUNCTION("""COMPUTED_VALUE"""),"SEM REDESPACHO") -> SEM REDESPACHO | P20: =IFERROR(__xludf.DUMMYFUNCTION("""COMPUTED_VALUE"""),"Pedido reprocessado ao alterar dados do cliente 21/10/2025 14:08:08 usuário: P000697112 ABATER O VALOR DE R$ 60.000,00 DA COMISSÃO QUE A INFRAH TEM A RECEBER DO HOTEL VILLA LOBOS E PARCELAR O RESTANTE. CONVERSAR COM A PRISCILLA, POIS ESSE PEDIDO SAIRÁ CO"&"M UM VALOR DE NF. MENOR. Pedido gerado através do PedidoEletronico.com - Transportadora / telefone: FITLOG TRANSPORTES E LOGISTICA LTDA / (048) 996277956Informação Adicional: ENDEREÇO DE ENTREGA: HOTEL ÍBIS BUDGET PAULISTA - RUA DA CONSOLAÇÃO, 2.303 - CO"&"NSOLAÇÃO - SÃO PAULO - SP - CEP: 01301-100, LIGAR PARA O ALISSON ANTES DE ENTREGAR - (11) 9 9473 5150. / E-mail para nota fiscal: , E-mail de cobrança: , Telefone para contato") -> Pedido reprocessado ao alterar dados do cliente 21/10/2025 14:08:08 usuário: P000697112 ABATER O VALOR DE R$ 60.000,00 DA COMISSÃO QUE A INFRAH TEM A RECEBER DO HOTEL VILLA LOBOS E PARCELAR O RESTANTE. CONVERSAR COM A PRISCILLA, POIS ESSE PEDIDO SAIRÁ COM UM VALOR DE NF. MENOR. Pedido gerado através do PedidoEletronico.com - Transportadora / telefone: FITLOG TRANSPORTES E LOGISTICA LTDA / (048) 996277956Informação Adicional: ENDEREÇO DE ENTREGA: HOTEL ÍBIS BUDGET PAULISTA - RUA DA CONSOLAÇÃO, 2.303 - CONSOLAÇÃO - SÃO PAULO - SP - CEP: 01301-100, LIGAR PARA O ALISSON ANTES DE ENTREGAR - (11) 9 9473 5150. / E-mail para nota fiscal: , E-mail de cobrança: , Telefone para contato
A21: =IFERROR(__xludf.DUMMYFUNCTION("""COMPUTED_VALUE"""),"18932-C") -> 18932-C | B21: =IFERROR(__xludf.DUMMYFUNCTION("""COMPUTED_VALUE"""),"INFRAH ENGENHARIA , INSTALACOES E SISTEMAS DE AQUECIMENTO LTDA") -> INFRAH ENGENHARIA , INSTALACOES E SISTEMAS DE AQUECIMENTO LTDA | C21: =IFERROR(__xludf.DUMMYFUNCTION("""COMPUTED_VALUE"""),0.0) -> 0 | E21: =IFERROR(__xludf.DUMMYFUNCTION("""COMPUTED_VALUE"""),"FH160L60T") -> FH160L60T | F21: =IFERROR(__xludf.DUMMYFUNCTION("""COMPUTED_VALUE"""),"TOUCH") -> TOUCH | G21: =IFERROR(__xludf.DUMMYFUNCTION("""COMPUTED_VALUE"""),"NAO") -> NAO | H21: =IFERROR(__xludf.DUMMYFUNCTION("""COMPUTED_VALUE"""),"NAO") -> NAO | I21: =IFERROR(__xludf.DUMMYFUNCTION("""COMPUTED_VALUE"""),"EM ABERTO") -> EM ABERTO | J21: =IFERROR(__xludf.DUMMYFUNCTION("""COMPUTED_VALUE"""),"FITLOG") -> FITLOG | K21: =IFERROR(__xludf.DUMMYFUNCTION("""COMPUTED_VALUE"""),"SEM REDESPACHO") -> SEM REDESPACHO | P21: =IFERROR(__xludf.DUMMYFUNCTION("""COMPUTED_VALUE"""),"Pedido reprocessado ao alterar dados do cliente 21/10/2025 14:08:08 usuário: P000697112 ABATER O VALOR DE R$ 60.000,00 DA COMISSÃO QUE A INFRAH TEM A RECEBER DO HOTEL VILLA LOBOS E PARCELAR O RESTANTE. CONVERSAR COM A PRISCILLA, POIS ESSE PEDIDO SAIRÁ CO"&"M UM VALOR DE NF. MENOR. Pedido gerado através do PedidoEletronico.com - Transportadora / telefone: FITLOG TRANSPORTES E LOGISTICA LTDA / (048) 996277956Informação Adicional: ENDEREÇO DE ENTREGA: HOTEL ÍBIS BUDGET PAULISTA - RUA DA CONSOLAÇÃO, 2.303 - CO"&"NSOLAÇÃO - SÃO PAULO - SP - CEP: 01301-100, LIGAR PARA O ALISSON ANTES DE ENTREGAR - (11) 9 9473 5150. / E-mail para nota fiscal: , E-mail de cobrança: , Telefone para contato") -> Pedido reprocessado ao alterar dados do cliente 21/10/2025 14:08:08 usuário: P000697112 ABATER O VALOR DE R$ 60.000,00 DA COMISSÃO QUE A INFRAH TEM A RECEBER DO HOTEL VILLA LOBOS E PARCELAR O RESTANTE. CONVERSAR COM A PRISCILLA, POIS ESSE PEDIDO SAIRÁ COM UM VALOR DE NF. MENOR. Pedido gerado através do PedidoEletronico.com - Transportadora / telefone: FITLOG TRANSPORTES E LOGISTICA LTDA / (048) 996277956Informação Adicional: ENDEREÇO DE ENTREGA: HOTEL ÍBIS BUDGET PAULISTA - RUA DA CONSOLAÇÃO, 2.303 - CONSOLAÇÃO - SÃO PAULO - SP - CEP: 01301-100, LIGAR PARA O ALISSON ANTES DE ENTREGAR - (11) 9 9473 5150. / E-mail para nota fiscal: , E-mail de cobrança: , Telefone para contato
A22: =IFERROR(__xludf.DUMMYFUNCTION("""COMPUTED_VALUE"""),"18932-D") -> 18932-D | B22: =IFERROR(__xludf.DUMMYFUNCTION("""COMPUTED_VALUE"""),"INFRAH ENGENHARIA , INSTALACOES E SISTEMAS DE AQUECIMENTO LTDA") -> INFRAH ENGENHARIA , INSTALACOES E SISTEMAS DE AQUECIMENTO LTDA | C22: =IFERROR(__xludf.DUMMYFUNCTION("""COMPUTED_VALUE"""),0.0) -> 0 | E22: =IFERROR(__xludf.DUMMYFUNCTION("""COMPUTED_VALUE"""),"FH160L60T") -> FH160L60T | F22: =IFERROR(__xludf.DUMMYFUNCTION("""COMPUTED_VALUE"""),"TOUCH") -> TOUCH | G22: =IFERROR(__xludf.DUMMYFUNCTION("""COMPUTED_VALUE"""),"NAO") -> NAO | H22: =IFERROR(__xludf.DUMMYFUNCTION("""COMPUTED_VALUE"""),"NAO") -> NAO | I22: =IFERROR(__xludf.DUMMYFUNCTION("""COMPUTED_VALUE"""),"EM ABERTO") -> EM ABERTO | J22: =IFERROR(__xludf.DUMMYFUNCTION("""COMPUTED_VALUE"""),"FITLOG") -> FITLOG | K22: =IFERROR(__xludf.DUMMYFUNCTION("""COMPUTED_VALUE"""),"SEM REDESPACHO") -> SEM REDESPACHO | P22: =IFERROR(__xludf.DUMMYFUNCTION("""COMPUTED_VALUE"""),"Pedido reprocessado ao alterar dados do cliente 21/10/2025 14:08:08 usuário: P000697112 ABATER O VALOR DE R$ 60.000,00 DA COMISSÃO QUE A INFRAH TEM A RECEBER DO HOTEL VILLA LOBOS E PARCELAR O RESTANTE. CONVERSAR COM A PRISCILLA, POIS ESSE PEDIDO SAIRÁ CO"&"M UM VALOR DE NF. MENOR. Pedido gerado através do PedidoEletronico.com - Transportadora / telefone: FITLOG TRANSPORTES E LOGISTICA LTDA / (048) 996277956Informação Adicional: ENDEREÇO DE ENTREGA: HOTEL ÍBIS BUDGET PAULISTA - RUA DA CONSOLAÇÃO, 2.303 - CO"&"NSOLAÇÃO - SÃO PAULO - SP - CEP: 01301-100, LIGAR PARA O ALISSON ANTES DE ENTREGAR - (11) 9 9473 5150. / E-mail para nota fiscal: , E-mail de cobrança: , Telefone para contato") -> Pedido reprocessado ao alterar dados do cliente 21/10/2025 14:08:08 usuário: P000697112 ABATER O VALOR DE R$ 60.000,00 DA COMISSÃO QUE A INFRAH TEM A RECEBER DO HOTEL VILLA LOBOS E PARCELAR O RESTANTE. CONVERSAR COM A PRISCILLA, POIS ESSE PEDIDO SAIRÁ COM UM VALOR DE NF. MENOR. Pedido gerado através do PedidoEletronico.com - Transportadora / telefone: FITLOG TRANSPORTES E LOGISTICA LTDA / (048) 996277956Informação Adicional: ENDEREÇO DE ENTREGA: HOTEL ÍBIS BUDGET PAULISTA - RUA DA CONSOLAÇÃO, 2.303 - CONSOLAÇÃO - SÃO PAULO - SP - CEP: 01301-100, LIGAR PARA O ALISSON ANTES DE ENTREGAR - (11) 9 9473 5150. / E-mail para nota fiscal: , E-mail de cobrança: , Telefone para contato
A23: =IFERROR(__xludf.DUMMYFUNCTION("""COMPUTED_VALUE"""),"18923-B") -> 18923-B | B23: =IFERROR(__xludf.DUMMYFUNCTION("""COMPUTED_VALUE"""),"HYDRONIC SOLUTIONS") -> HYDRONIC SOLUTIONS | C23: =IFERROR(__xludf.DUMMYFUNCTION("""COMPUTED_VALUE"""),0.0) -> 0 | E23: =IFERROR(__xludf.DUMMYFUNCTION("""COMPUTED_VALUE"""),"FH80F60W") -> FH80F60W | G23: =IFERROR(__xludf.DUMMYFUNCTION("""COMPUTED_VALUE"""),"NAO") -> NAO | H23: =IFERROR(__xludf.DUMMYFUNCTION("""COMPUTED_VALUE"""),"NAO") -> NAO | I23: =IFERROR(__xludf.DUMMYFUNCTION("""COMPUTED_VALUE"""),"EM ABERTO") -> EM ABERTO | J23: =IFERROR(__xludf.DUMMYFUNCTION("""COMPUTED_VALUE"""),"FITLOG") -> FITLOG | K23: =IFERROR(__xludf.DUMMYFUNCTION("""COMPUTED_VALUE"""),"SEM REDESPACHO") -> SEM REDESPACHO | P23: =IFERROR(__xludf.DUMMYFUNCTION("""COMPUTED_VALUE"""),"Pedido gerado através do PedidoEletronico.com - Transportadora / telefone: FITLOG TRANSPORTES E LOGISTICA LTDA / (048) 996277956Obs.Interna: entrega futura. Entregar hotel BIARRITZ COPACABANA Rua Aires Saldanha 54 Copacabana cep 22440 032 RJ . Maquinas "&"ja implantadas anteriormente. Pedido para correção de endereço de entrega . Ligar para o Luiz antes de entregar 21 9 6518 9999 / E-mail para nota fiscal: , E-mail de cobrança: , Telefone para contato") -> Pedido gerado através do PedidoEletronico.com - Transportadora / telefone: FITLOG TRANSPORTES E LOGISTICA LTDA / (048) 996277956Obs.Interna: entrega futura. Entregar hotel BIARRITZ COPACABANA Rua Aires Saldanha 54 Copacabana cep 22440 032 RJ . Maquinas ja implantadas anteriormente. Pedido para correção de endereço de entrega . Ligar para o Luiz antes de entregar 21 9 6518 9999 / E-mail para nota fiscal: , E-mail de cobrança: , Telefone para contato
A24: =IFERROR(__xludf.DUMMYFUNCTION("""COMPUTED_VALUE"""),"18793") -> 18793 | B24: =IFERROR(__xludf.DUMMYFUNCTION("""COMPUTED_VALUE"""),"DESJOYAUX ES") -> DESJOYAUX ES | C24: =IFERROR(__xludf.DUMMYFUNCTION("""COMPUTED_VALUE"""),1.0) -> 1 | D24: =IFERROR(__xludf.DUMMYFUNCTION("""COMPUTED_VALUE"""),20433.0) -> 20433 | E24: =IFERROR(__xludf.DUMMYFUNCTION("""COMPUTED_VALUE"""),"FTI75DPTBR") -> FTI75DPTBR | F24: =IFERROR(__xludf.DUMMYFUNCTION("""COMPUTED_VALUE"""),"WI-FI") -> WI-FI | G24: =IFERROR(__xludf.DUMMYFUNCTION("""COMPUTED_VALUE"""),"NAO") -> NAO | H24: =IFERROR(__xludf.DUMMYFUNCTION("""COMPUTED_VALUE"""),"NAO") -> NAO | I24: =IFERROR(__xludf.DUMMYFUNCTION("""COMPUTED_VALUE"""),"PRODUÇÃO") -> PRODUÇÃO | J24: =IFERROR(__xludf.DUMMYFUNCTION("""COMPUTED_VALUE"""),"FITLOG") -> FITLOG | K24: =IFERROR(__xludf.DUMMYFUNCTION("""COMPUTED_VALUE"""),"SEM REDESPACHO") -> SEM REDESPACHO | P24: =IFERROR(__xludf.DUMMYFUNCTION("""COMPUTED_VALUE"""),"FITLOG TRANSPORTES E LOGISTICA LTDA / (048) 996277956Informação Adicional: CAROLINA / E-mail para nota fiscal: , E-mail de cobrança: , Telefone para contato") -> FITLOG TRANSPORTES E LOGISTICA LTDA / (048) 996277956Informação Adicional: CAROLINA / E-mail para nota fiscal: , E-mail de cobrança: , Telefone para contato
A25: =IFERROR(__xludf.DUMMYFUNCTION("""COMPUTED_VALUE"""),"18871-A") -> 18871-A | B25: =IFERROR(__xludf.DUMMYFUNCTION("""COMPUTED_VALUE"""),"STEINFIBER") -> STEINFIBER | C25: =IFERROR(__xludf.DUMMYFUNCTION("""COMPUTED_VALUE"""),0.0) -> 0 | D25: =IFERROR(__xludf.DUMMYFUNCTION("""COMPUTED_VALUE"""),20385.0) -> 20385 | E25: =IFERROR(__xludf.DUMMYFUNCTION("""COMPUTED_VALUE"""),"FTI145LPTBR") -> FTI145LPTBR | F25: =IFERROR(__xludf.DUMMYFUNCTION("""COMPUTED_VALUE"""),"WI-FI") -> WI-FI | G25: =IFERROR(__xludf.DUMMYFUNCTION("""COMPUTED_VALUE"""),"NAO") -> NAO | H25: =IFERROR(__xludf.DUMMYFUNCTION("""COMPUTED_VALUE"""),"NAO") -> NAO | I25: =IFERROR(__xludf.DUMMYFUNCTION("""COMPUTED_VALUE"""),"PRODUÇÃO") -> PRODUÇÃO | J25: =IFERROR(__xludf.DUMMYFUNCTION("""COMPUTED_VALUE"""),"RETIRA") -> RETIRA | K25: =IFERROR(__xludf.DUMMYFUNCTION("""COMPUTED_VALUE"""),"SEM REDESPACHO") -> SEM REDESPACHO | P25: =IFERROR(__xludf.DUMMYFUNCTION("""COMPUTED_VALUE"""),"CLIENTE RETIRA / (0) Informação Adicional: PREÇO NEGOCIADO R$ 18.600,00 - ALTERAR NO PEDIDO - AUTORIZADO POR PRISCILLA ENTREGA: 01 MÁQUINA DIA 20/10 E AS OUTRAS 06 MAXIMO DIA 05/11 / E-mail para nota fiscal: , E-mail de cobrança: , Telefone para contat"&"o") -> CLIENTE RETIRA / (0) Informação Adicional: PREÇO NEGOCIADO R$ 18.600,00 - ALTERAR NO PEDIDO - AUTORIZADO POR PRISCILLA ENTREGA: 01 MÁQUINA DIA 20/10 E AS OUTRAS 06 MAXIMO DIA 05/11 / E-mail para nota fiscal: , E-mail de cobrança: , Telefone para contato
A26: =IFERROR(__xludf.DUMMYFUNCTION("""COMPUTED_VALUE"""),"18891") -> 18891 | B26: =IFERROR(__xludf.DUMMYFUNCTION("""COMPUTED_VALUE"""),"KYP COMERCIO DE EQUIPAMENTOS PARA PISCINAS LTDA") -> KYP COMERCIO DE EQUIPAMENTOS PARA PISCINAS LTDA | C26: =IFERROR(__xludf.DUMMYFUNCTION("""COMPUTED_VALUE"""),0.0) -> 0 | D26: =IFERROR(__xludf.DUMMYFUNCTION("""COMPUTED_VALUE"""),20377.0) -> 20377 | E26: =IFERROR(__xludf.DUMMYFUNCTION("""COMPUTED_VALUE"""),"FT80B35W") -> FT80B35W | F26: =IFERROR(__xludf.DUMMYFUNCTION("""COMPUTED_VALUE"""),"WI-FI") -> WI-FI | G26: =IFERROR(__xludf.DUMMYFUNCTION("""COMPUTED_VALUE"""),"NAO") -> NAO | H26: =IFERROR(__xludf.DUMMYFUNCTION("""COMPUTED_VALUE"""),"NAO") -> NAO | I26: =IFERROR(__xludf.DUMMYFUNCTION("""COMPUTED_VALUE"""),"TESTAR") -> TESTAR | J26: =IFERROR(__xludf.DUMMYFUNCTION("""COMPUTED_VALUE"""),"FITLOG") -> FITLOG | K26: =IFERROR(__xludf.DUMMYFUNCTION("""COMPUTED_VALUE"""),"SEM REDESPACHO") -> SEM REDESPACHO | P26: =IFERROR(__xludf.DUMMYFUNCTION("""COMPUTED_VALUE"""),"FITLOG TRANSPORTES E LOGISTICA LTDA / (048) 996277956E-mail para nota fiscal: , E-mail de cobrança: , Telefone para contato") -> FITLOG TRANSPORTES E LOGISTICA LTDA / (048) 996277956E-mail para nota fiscal: , E-mail de cobrança: , Telefone para contato
A27: =IFERROR(__xludf.DUMMYFUNCTION("""COMPUTED_VALUE"""),"18912") -> 18912 | B27: =IFERROR(__xludf.DUMMYFUNCTION("""COMPUTED_VALUE"""),"D.K. SOLUÇÕES") -> D.K. SOLUÇÕES | C27: =IFERROR(__xludf.DUMMYFUNCTION("""COMPUTED_VALUE"""),90.0) -> 90 | E27: =IFERROR(__xludf.DUMMYFUNCTION("""COMPUTED_VALUE"""),"FTI75D40PT") -> FTI75D40PT | F27: =IFERROR(__xludf.DUMMYFUNCTION("""COMPUTED_VALUE"""),"WI-FI") -> WI-FI | G27: =IFERROR(__xludf.DUMMYFUNCTION("""COMPUTED_VALUE"""),"NAO") -> NAO | H27: =IFERROR(__xludf.DUMMYFUNCTION("""COMPUTED_VALUE"""),"NAO") -> NAO | I27: =IFERROR(__xludf.DUMMYFUNCTION("""COMPUTED_VALUE"""),"TESTAR") -> TESTAR | J27: =IFERROR(__xludf.DUMMYFUNCTION("""COMPUTED_VALUE"""),"RETIRA") -> RETIRA | K27: =IFERROR(__xludf.DUMMYFUNCTION("""COMPUTED_VALUE"""),"SEM REDESPACHO") -> SEM REDESPACHO | P27: =IFERROR(__xludf.DUMMYFUNCTION("""COMPUTED_VALUE"""),"Pedido gerado através do PedidoEletronico.com - Transportadora / telefone: CLIENTE RETIRA / (0) Informação Adicional: cliente retira / E-mail para nota fiscal: , E-mail de cobrança: , Telefone para contato") -> Pedido gerado através do PedidoEletronico.com - Transportadora / telefone: CLIENTE RETIRA / (0) Informação Adicional: cliente retira / E-mail para nota fiscal: , E-mail de cobrança: , Telefone para contato
